<?xml version="1.0"?>
<sdf version='1.6'>
  <world name='default'>
    <light name='sun' type='directional'>
      <cast_shadows>1</cast_shadows>
      <pose frame=''>0 0 10 0 -0 0</pose>
      <diffuse>0.8 0.8 0.8 1</diffuse>
      <specular>0.2 0.2 0.2 1</specular>
      <attenuation>
        <range>1000</range>
        <constant>0.9</constant>
        <linear>0.01</linear>
        <quadratic>0.001</quadratic>
      </attenuation>
      <direction>-0.5 0.1 -0.9</direction>
    </light>
    <model name='ground_plane'>
      <static>1</static>
      <link name='link'>
        <collision name='collision'>
          <geometry>
            <plane>
              <normal>0 0 1</normal>
              <size>100 100</size>
            </plane>
          </geometry>
          <surface>
            <contact>
              <collide_bitmask>65535</collide_bitmask>
              <ode/>
            </contact>
            <friction>
              <ode>
                <mu>100</mu>
                <mu2>50</mu2>
              </ode>
              <torsional>
                <ode/>
              </torsional>
            </friction>
            <bounce/>
          </surface>
          <max_contacts>10</max_contacts>
        </collision>
        <visual name='visual'>
          <cast_shadows>0</cast_shadows>
          <geometry>
            <plane>
              <normal>0 0 1</normal>
              <size>100 100</size>
            </plane>
          </geometry>
          <material>
            <script>
              <uri>file://media/materials/scripts/gazebo.material</uri>
              <name>Gazebo/Grey</name>
            </script>
          </material>
        </visual>
        <self_collide>0</self_collide>
        <enable_wind>0</enable_wind>
        <kinematic>0</kinematic>
      </link>
    </model>
    <gravity>0 0 -9.8</gravity>
    <magnetic_field>6e-06 2.3e-05 -4.2e-05</magnetic_field>
    <atmosphere type='adiabatic'/>
    <physics name='default_physics' default='0' type='ode'>
      <max_step_size>0.001</max_step_size>
      <real_time_factor>1</real_time_factor>
      <real_time_update_rate>1000</real_time_update_rate>
    </physics>
    <scene>
      <ambient>0.4 0.4 0.4 1</ambient>
      <background>0.7 0.7 0.7 1</background>
      <shadows>1</shadows>
    </scene>
    <audio>
      <device>default</device>
    </audio>
    <wind/>
    <spherical_coordinates>
      <surface_model>EARTH_WGS84</surface_model>
      <latitude_deg>0</latitude_deg>
      <longitude_deg>0</longitude_deg>
      <elevation>0</elevation>
      <heading_deg>0</heading_deg>
    </spherical_coordinates>
    <model name='robotiq_c2_model'>
      <link name='box'>
        <pose frame=''>0 0 0.3 0 -0 0</pose>
        <inertial>
          <pose frame=''>0 0 0 0 -0 0</pose>
          <mass>1</mass>
          <inertia>
            <ixx>1</ixx>
            <ixy>0</ixy>
            <ixz>0</ixz>
            <iyy>1</iyy>
            <iyz>0</iyz>
            <izz>1</izz>
          </inertia>
        </inertial>
        <collision name='box_collision'>
          <pose frame=''>0 0 0 0 -0 0</pose>
          <geometry>
            <box>
              <size>1 0.05 0.6</size>
            </box>
          </geometry>
          <surface>
            <contact>
              <ode>
                <kp>1e+06</kp>
                <kd>1</kd>
              </ode>
            </contact>
            <friction>
              <ode>
                <mu>50</mu>
                <mu2>50</mu2>
              </ode>
              <torsional>
                <ode/>
              </torsional>
            </friction>
            <bounce/>
          </surface>
          <max_contacts>10</max_contacts>
        </collision>
        <visual name='box_visual'>
          <pose frame=''>0 0 0 0 -0 0</pose>
          <geometry>
            <box>
              <size>1 0.05 0.6</size>
            </box>
          </geometry>
          <material>
            <script>
              <name>Gazebo/Grey</name>
              <uri>file://media/materials/scripts/gazebo.material</uri>
            </script>
          </material>
        </visual>
        <gravity>1</gravity>
        <velocity_decay/>
        <self_collide>0</self_collide>
        <enable_wind>0</enable_wind>
        <kinematic>0</kinematic>
      </link>
      <joint name='rh_world_joint' type='fixed'>
        <child>box</child>
        <parent>world</parent>
      </joint>
      <link name='arm_base_link'>
        <pose frame=''>0 0 0.625 0 -0 0</pose>
        <inertial>
          <pose frame=''>0 0 0 0 -0 0</pose>
          <mass>1</mass>
          <inertia>
            <ixx>1</ixx>
            <ixy>0</ixy>
            <ixz>0</ixz>
            <iyy>1</iyy>
            <iyz>0</iyz>
            <izz>1</izz>
          </inertia>
        </inertial>
        <collision name='arm_base_link_collision'>
          <pose frame=''>0 0 0 0 -0 0</pose>
          <geometry>
            <box>
              <size>0.05 0.05 0.05</size>
            </box>
          </geometry>
          <surface>
            <contact>
              <ode>
                <kp>1e+06</kp>
                <kd>1</kd>
              </ode>
            </contact>
            <friction>
              <ode>
                <mu>50</mu>
                <mu2>50</mu2>
              </ode>
              <torsional>
                <ode/>
              </torsional>
            </friction>
            <bounce/>
          </surface>
          <max_contacts>10</max_contacts>
        </collision>
        <visual name='arm_base_link_visual'>
          <pose frame=''>0 0 0 0 -0 0</pose>
          <geometry>
            <box>
              <size>0.05 0.05 0.05</size>
            </box>
          </geometry>
          <material>
            <script>
              <name>Gazebo/Red</name>
              <uri>file://media/materials/scripts/gazebo.material</uri>
            </script>
          </material>
        </visual>
        <gravity>1</gravity>
        <velocity_decay/>
        <self_collide>0</self_collide>
        <enable_wind>0</enable_wind>
        <kinematic>0</kinematic>
      </link>
      <joint name='arm_base' type='prismatic'>
        <child>arm_base_link</child>
        <parent>box</parent>
        <axis>
          <xyz>1 0 0</xyz>
          <limit>
            <lower>-0.45</lower>
            <upper>0.45</upper>
            <effort>10000</effort>
            <velocity>0.2</velocity>
          </limit>
          <dynamics>
            <spring_reference>0</spring_reference>
            <spring_stiffness>0</spring_stiffness>
          </dynamics>
          <use_parent_model_frame>1</use_parent_model_frame>
        </axis>
      </joint>
      <link name='joint_a1_link'>
        <pose frame=''>0 0 0.675 0 -0 1.57</pose>
        <inertial>
          <pose frame=''>-0.201367 0 -0.0195 0 -0 0</pose>
          <mass>3</mass>
          <inertia>
            <ixx>3.00061</ixx>
            <ixy>0</ixy>
            <ixz>-0.0059074</ixz>
            <iyy>3.06144</iyy>
            <iyz>0</iyz>
            <izz>3.06083</izz>
          </inertia>
        </inertial>
        <collision name='joint_a1_link_collision'>
          <pose frame=''>0 0 0 0 -0 0</pose>
          <geometry>
            <box>
              <size>0.7 0.05 0.05</size>
            </box>
          </geometry>
          <surface>
            <contact>
              <ode>
                <kp>1e+06</kp>
                <kd>1</kd>
              </ode>
            </contact>
            <friction>
              <ode>
                <mu>50</mu>
                <mu2>50</mu2>
              </ode>
              <torsional>
                <ode/>
              </torsional>
            </friction>
            <bounce/>
          </surface>
          <max_contacts>10</max_contacts>
        </collision>
        <collision name='joint_a1_link_fixed_joint_lump__robotiq_85_adapter_link_collision_1'>
          <pose frame=''>-0.3 0 -0.025 1.57 9.6e-05 1.5708</pose>
          <geometry>
            <mesh>
              <scale>1 1 1</scale>
              <uri>/home/katerina/catkin_ws/src/robotiq/robotiq_2f_c2_gripper_visualization/meshes/robotiq_c2/collision/robotiq_85_gripper_adapter_plate.dae</uri>
            </mesh>
          </geometry>
          <max_contacts>10</max_contacts>
          <surface>
            <contact>
              <ode/>
            </contact>
            <bounce/>
            <friction>
              <torsional>
                <ode/>
              </torsional>
              <ode/>
            </friction>
          </surface>
        </collision>
        <collision name='joint_a1_link_fixed_joint_lump__robotiq_85_base_link_collision_2'>
          <pose frame=''>-0.304093 0 -0.033503 3.1407 9.6e-05 1.5708</pose>
          <geometry>
            <mesh>
              <scale>1 1 1</scale>
              <uri>/home/katerina/catkin_ws/src/robotiq/robotiq_2f_c2_gripper_visualization/meshes/robotiq_c2/collision/robotiq_85_gripper_base.dae</uri>
            </mesh>
          </geometry>
          <max_contacts>10</max_contacts>
          <surface>
            <contact>
              <ode/>
            </contact>
            <bounce/>
            <friction>
              <torsional>
                <ode/>
              </torsional>
              <ode/>
            </friction>
          </surface>
        </collision>
        <visual name='joint_a1_link_visual'>
          <pose frame=''>0 0 0 0 -0 0</pose>
          <geometry>
            <box>
              <size>0.7 0.05 0.05</size>
            </box>
          </geometry>
          <material>
            <script>
              <name>Gazebo/Red</name>
              <uri>file://media/materials/scripts/gazebo.material</uri>
            </script>
          </material>
        </visual>
        <visual name='joint_a1_link_fixed_joint_lump__robotiq_85_adapter_link_visual_1'>
          <pose frame=''>-0.3 0 -0.025 3.1407 9.6e-05 1.5708</pose>
          <geometry>
            <mesh>
              <scale>1 1 1</scale>
              <uri>/home/katerina/catkin_ws/src/robotiq/robotiq_2f_c2_gripper_visualization/meshes/robotiq_c2/visual/robotiq_85_gripper_adapter_plate.dae</uri>
            </mesh>
          </geometry>
        </visual>
        <visual name='joint_a1_link_fixed_joint_lump__robotiq_85_base_link_visual_2'>
          <pose frame=''>-0.304093 0 -0.033503 -1.57169 9.6e-05 1.5708</pose>
          <geometry>
            <mesh>
              <scale>1 1 1</scale>
              <uri>/home/katerina/catkin_ws/src/robotiq/robotiq_2f_c2_gripper_visualization/meshes/robotiq_c2/visual/robotiq_85_gripper_base.dae</uri>
            </mesh>
          </geometry>
        </visual>
        <gravity>0</gravity>
        <velocity_decay/>
        <self_collide>0</self_collide>
        <enable_wind>0</enable_wind>
        <kinematic>0</kinematic>
      </link>
      <joint name='joint_a1' type='prismatic'>
        <child>joint_a1_link</child>
        <parent>arm_base_link</parent>
        <axis>
          <xyz>0.000796 1 0</xyz>
          <limit>
            <lower>-0.35</lower>
            <upper>0.15</upper>
            <effort>10000</effort>
            <velocity>0.2</velocity>
          </limit>
          <dynamics>
            <spring_reference>0</spring_reference>
            <spring_stiffness>0</spring_stiffness>
          </dynamics>
          <use_parent_model_frame>1</use_parent_model_frame>
        </axis>
      </joint>
      <link name='robotiq_85_left_inner_knuckle_link'>
        <pose frame=''>-0.012942 -0.304044 0.593067 -1.57089 0.000893 -1.57159</pose>
        <inertial>
          <pose frame=''>0 0 0 0 -0 0</pose>
          <mass>1</mass>
          <inertia>
            <ixx>1</ixx>
            <ixy>0</ixy>
            <ixz>0</ixz>
            <iyy>1</iyy>
            <iyz>0</iyz>
            <izz>1</izz>
          </inertia>
        </inertial>
        <collision name='robotiq_85_left_inner_knuckle_link_collision'>
          <pose frame=''>0 -0.04843 0.0127 3.14159 1.57079 -1.57079</pose>
          <geometry>
            <mesh>
              <scale>1 1 1</scale>
              <uri>/home/katerina/catkin_ws/src/robotiq/robotiq_2f_c2_gripper_visualization/meshes/robotiq_c2/collision/robotiq_85_gripper_joint_2_L.dae</uri>
            </mesh>
          </geometry>
          <max_contacts>10</max_contacts>
          <surface>
            <contact>
              <ode/>
            </contact>
            <bounce/>
            <friction>
              <torsional>
                <ode/>
              </torsional>
              <ode/>
            </friction>
          </surface>
        </collision>
        <visual name='robotiq_85_left_inner_knuckle_link_visual'>
          <pose frame=''>0 -0.04843 0.0127 3.14159 1.57079 3.14159</pose>
          <geometry>
            <mesh>
              <scale>1 1 1</scale>
              <uri>/home/katerina/catkin_ws/src/robotiq/robotiq_2f_c2_gripper_visualization/meshes/robotiq_c2/visual/robotiq_85_gripper_joint_2_L.dae</uri>
            </mesh>
          </geometry>
        </visual>
        <self_collide>0</self_collide>
        <enable_wind>0</enable_wind>
        <kinematic>0</kinematic>
      </link>
      <joint name='robotiq_85_left_inner_knuckle_joint' type='revolute'>
        <child>robotiq_85_left_inner_knuckle_link</child>
        <parent>joint_a1_link</parent>
        <axis>
          <xyz>-0.000796 -0.999999 -0.000893</xyz>
          <limit>
            <lower>0</lower>
            <upper>1.5707</upper>
            <effort>1000</effort>
            <velocity>2</velocity>
          </limit>
          <dynamics>
            <spring_reference>0</spring_reference>
            <spring_stiffness>0</spring_stiffness>
          </dynamics>
          <use_parent_model_frame>1</use_parent_model_frame>
        </axis>
      </joint>
      <link name='robotiq_85_left_finger_tip_link'>
        <pose frame=''>-0.051746 -0.303976 0.551111 -1.57089 0.000893 -1.57159</pose>
        <inertial>
          <pose frame=''>0 0 0 0 -0 0</pose>
          <mass>1</mass>
          <inertia>
            <ixx>1</ixx>
            <ixy>0</ixy>
            <ixz>0</ixz>
            <iyy>1</iyy>
            <iyz>0</iyz>
            <izz>1</izz>
          </inertia>
        </inertial>
        <collision name='robotiq_85_left_finger_tip_link_collision'>
          <pose frame=''>0 -0.090381 0.051505 3.14159 1.57079 -1.57079</pose>
          <geometry>
            <mesh>
              <scale>1 1 1</scale>
              <uri>/home/katerina/catkin_ws/src/robotiq/robotiq_2f_c2_gripper_visualization/meshes/robotiq_c2/collision/robotiq_85_gripper_joint_3_L.dae</uri>
            </mesh>
          </geometry>
          <max_contacts>10</max_contacts>
          <surface>
            <contact>
              <ode/>
            </contact>
            <bounce/>
            <friction>
              <torsional>
                <ode/>
              </torsional>
              <ode/>
            </friction>
          </surface>
        </collision>
        <visual name='robotiq_85_left_finger_tip_link_visual'>
          <pose frame=''>0 -0.090381 0.051505 3.14159 1.57079 3.14159</pose>
          <geometry>
            <mesh>
              <scale>1 1 1</scale>
              <uri>/home/katerina/catkin_ws/src/robotiq/robotiq_2f_c2_gripper_visualization/meshes/robotiq_c2/visual/robotiq_85_gripper_joint_3_L.dae</uri>
            </mesh>
          </geometry>
        </visual>
        <sensor name='my_contact' type='contact'>
        <plugin name="my_plugin" filename="libcontact.so"/>
          <contact>
            <collision>robotiq_85_left_finger_tip_link_collision</collision>
          </contact>
          <update_rate>5</update_rate>
        </sensor>
        <self_collide>0</self_collide>
        <enable_wind>0</enable_wind>
        <kinematic>0</kinematic>
      </link>
      <joint name='robotiq_85_left_finger_tip_joint' type='revolute'>
        <child>robotiq_85_left_finger_tip_link</child>
        <parent>robotiq_85_left_inner_knuckle_link</parent>
        <axis>
          <xyz>-0.000796 -0.999999 -0.000893</xyz>
          <limit>
            <lower>0</lower>
            <upper>1.5707</upper>
            <effort>1000</effort>
            <velocity>2</velocity>
          </limit>
          <dynamics>
            <spring_reference>0</spring_reference>
            <spring_stiffness>0</spring_stiffness>
          </dynamics>
          <use_parent_model_frame>1</use_parent_model_frame>
        </axis>
      </joint>
      <link name='robotiq_85_left_knuckle_link'>
        <pose frame=''>-0.030842 -0.304035 0.599587 1.57089 0.000893 -1.57159</pose>
        <inertial>
          <pose frame=''>0 0.00254 0.01567 0 -0 0</pose>
          <mass>2</mass>
          <inertia>
            <ixx>2.0005</ixx>
            <ixy>0</ixy>
            <ixz>0</ixz>
            <iyy>2.00049</iyy>
            <iyz>-7.96036e-05</iyz>
            <izz>2.00001</izz>
          </inertia>
        </inertial>
        <collision name='robotiq_85_left_knuckle_link_collision'>
          <pose frame=''>0 0.04191 -0.0306 -3.14159 -1.57079 -1.57079</pose>
          <geometry>
            <mesh>
              <scale>1 1 1</scale>
              <uri>/home/katerina/catkin_ws/src/robotiq/robotiq_2f_c2_gripper_visualization/meshes/robotiq_c2/collision/robotiq_85_gripper_joint_0_L.dae</uri>
            </mesh>
          </geometry>
          <max_contacts>10</max_contacts>
          <surface>
            <contact>
              <ode/>
            </contact>
            <bounce/>
            <friction>
              <torsional>
                <ode/>
              </torsional>
              <ode/>
            </friction>
          </surface>
        </collision>
        <collision name='robotiq_85_left_knuckle_link_fixed_joint_lump__robotiq_85_left_finger_link_collision_1'>
          <pose frame=''>0 0.041904 -0.030603 3.14159 -1.57079 -1.5706</pose>
          <geometry>
            <mesh>
              <scale>1 1 1</scale>
              <uri>/home/katerina/catkin_ws/src/robotiq/robotiq_2f_c2_gripper_visualization/meshes/robotiq_c2/collision/robotiq_85_gripper_joint_1_L.dae</uri>
            </mesh>
          </geometry>
          <max_contacts>10</max_contacts>
          <surface>
            <contact>
              <ode/>
            </contact>
            <bounce/>
            <friction>
              <torsional>
                <ode/>
              </torsional>
              <ode/>
            </friction>
          </surface>
        </collision>
        <visual name='robotiq_85_left_knuckle_link_visual'>
          <pose frame=''>0 0.04191 -0.0306 3.14159 -1.57079 -3e-06</pose>
          <geometry>
            <mesh>
              <scale>1 1 1</scale>
              <uri>/home/katerina/catkin_ws/src/robotiq/robotiq_2f_c2_gripper_visualization/meshes/robotiq_c2/visual/robotiq_85_gripper_joint_0_L.dae</uri>
            </mesh>
          </geometry>
        </visual>
        <visual name='robotiq_85_left_knuckle_link_fixed_joint_lump__robotiq_85_left_finger_link_visual_1'>
          <pose frame=''>0 0.041904 -0.030603 -3.14159 -1.57079 9.7e-05</pose>
          <geometry>
            <mesh>
              <scale>1 1 1</scale>
              <uri>/home/katerina/catkin_ws/src/robotiq/robotiq_2f_c2_gripper_visualization/meshes/robotiq_c2/visual/robotiq_85_gripper_joint_1_L.dae</uri>
            </mesh>
          </geometry>
        </visual>
        <self_collide>0</self_collide>
        <enable_wind>0</enable_wind>
        <kinematic>0</kinematic>
      </link>
      <joint name='robotiq_85_left_knuckle_joint' type='revolute'>
        <child>robotiq_85_left_knuckle_link</child>
        <parent>joint_a1_link</parent>
        <axis>
          <xyz>-0.000796 -0.999999 -0.000893</xyz>
          <limit>
            <lower>0</lower>
            <upper>0.8575</upper>
            <effort>1000</effort>
            <velocity>2</velocity>
          </limit>
          <dynamics>
            <spring_reference>0</spring_reference>
            <spring_stiffness>0</spring_stiffness>
          </dynamics>
          <use_parent_model_frame>1</use_parent_model_frame>
        </axis>
      </joint>
      <link name='robotiq_85_right_inner_knuckle_link'>
        <pose frame=''>0.012458 -0.304065 0.593067 -1.5707 -0.0007 1.57</pose>
        <inertial>
          <pose frame=''>0 0 0 0 -0 0</pose>
          <mass>1</mass>
          <inertia>
            <ixx>1</ixx>
            <ixy>0</ixy>
            <ixz>0</ixz>
            <iyy>1</iyy>
            <iyz>0</iyz>
            <izz>1</izz>
          </inertia>
        </inertial>
        <collision name='robotiq_85_right_inner_knuckle_link_collision'>
          <pose frame=''>0 -0.04843 0.0127 3.14159 -1.57079 1.57079</pose>
          <geometry>
            <mesh>
              <scale>1 1 1</scale>
              <uri>/home/katerina/catkin_ws/src/robotiq/robotiq_2f_c2_gripper_visualization/meshes/robotiq_c2/collision/robotiq_85_gripper_joint_2_R.dae</uri>
            </mesh>
          </geometry>
          <max_contacts>10</max_contacts>
          <surface>
            <contact>
              <ode/>
            </contact>
            <bounce/>
            <friction>
              <torsional>
                <ode/>
              </torsional>
              <ode/>
            </friction>
          </surface>
        </collision>
        <visual name='robotiq_85_right_inner_knuckle_link_visual'>
          <pose frame=''>0 -0.04843 0.0127 3.14159 -1.57079 3.14159</pose>
          <geometry>
            <mesh>
              <scale>1 1 1</scale>
              <uri>/home/katerina/catkin_ws/src/robotiq/robotiq_2f_c2_gripper_visualization/meshes/robotiq_c2/visual/robotiq_85_gripper_joint_2_R.dae</uri>
            </mesh>
          </geometry>
        </visual>
        <self_collide>0</self_collide>
        <enable_wind>0</enable_wind>
        <kinematic>0</kinematic>
      </link>
      <joint name='robotiq_85_right_inner_knuckle_joint' type='revolute'>
        <child>robotiq_85_right_inner_knuckle_link</child>
        <parent>joint_a1_link</parent>
        <axis>
          <xyz>0.000796 0.999999 0.0007</xyz>
          <limit>
            <lower>0</lower>
            <upper>1.5707</upper>
            <effort>1000</effort>
            <velocity>2</velocity>
          </limit>
          <dynamics>
            <spring_reference>0</spring_reference>
            <spring_stiffness>0</spring_stiffness>
          </dynamics>
          <use_parent_model_frame>1</use_parent_model_frame>
        </axis>
      </joint>
      <link name='robotiq_85_right_finger_tip_link'>
        <pose frame=''>0.051254 -0.304066 0.551103 -1.5707 -0.0007 1.57</pose>
        <inertial>
          <pose frame=''>0 0 0 0 -0 0</pose>
          <mass>1</mass>
          <inertia>
            <ixx>1</ixx>
            <ixy>0</ixy>
            <ixz>0</ixz>
            <iyy>1</iyy>
            <iyz>0</iyz>
            <izz>1</izz>
          </inertia>
        </inertial>
        <collision name='robotiq_85_right_finger_tip_link_collision'>
          <pose frame=''>0 -0.090381 0.051505 3.14159 -1.57079 1.57079</pose>
          <geometry>
            <mesh>
              <scale>1 1 1</scale>
              <uri>/home/katerina/catkin_ws/src/robotiq/robotiq_2f_c2_gripper_visualization/meshes/robotiq_c2/collision/robotiq_85_gripper_joint_3_R.dae</uri>
            </mesh>
          </geometry>
          <max_contacts>10</max_contacts>
          <surface>
            <contact>
              <ode/>
            </contact>
            <bounce/>
            <friction>
              <torsional>
                <ode/>
              </torsional>
              <ode/>
            </friction>
          </surface>
        </collision>
        <visual name='robotiq_85_right_finger_tip_link_visual'>
          <pose frame=''>0 -0.090381 0.051505 3.14159 -1.57079 3.14159</pose>
          <geometry>
            <mesh>
              <scale>1 1 1</scale>
              <uri>/home/katerina/catkin_ws/src/robotiq/robotiq_2f_c2_gripper_visualization/meshes/robotiq_c2/visual/robotiq_85_gripper_joint_3_R.dae</uri>
            </mesh>
          </geometry>
        </visual>
        <sensor name='my_contact' type='contact'>
        <plugin name="my_plugin" filename="libcontact.so"/>
          <contact>
            <collision>robotiq_85_right_finger_tip_link_collision</collision>
          </contact>
          <update_rate>5</update_rate>
        </sensor>
        <self_collide>0</self_collide>
        <enable_wind>0</enable_wind>
        <kinematic>0</kinematic>
      </link>
      <joint name='robotiq_85_right_finger_tip_joint' type='revolute'>
        <child>robotiq_85_right_finger_tip_link</child>
        <parent>robotiq_85_right_inner_knuckle_link</parent>
        <axis>
          <xyz>0.000796 0.999999 0.0007</xyz>
          <limit>
            <lower>0</lower>
            <upper>1.5707</upper>
            <effort>1000</effort>
            <velocity>2</velocity>
          </limit>
          <dynamics>
            <spring_reference>0</spring_reference>
            <spring_stiffness>0</spring_stiffness>
          </dynamics>
          <use_parent_model_frame>1</use_parent_model_frame>
        </axis>
      </joint>
      <link name='robotiq_85_right_knuckle_link'>
        <pose frame=''>0.030358 -0.304084 0.599587 1.5707 -0.0007 1.57</pose>
        <inertial>
          <pose frame=''>0 0.00254 0.01567 0 -0 0</pose>
          <mass>2</mass>
          <inertia>
            <ixx>2.0005</ixx>
            <ixy>0</ixy>
            <ixz>0</ixz>
            <iyy>2.00049</iyy>
            <iyz>-7.96036e-05</iyz>
            <izz>2.00001</izz>
          </inertia>
        </inertial>
        <collision name='robotiq_85_right_knuckle_link_collision'>
          <pose frame=''>0 0.04191 -0.0306 -3.14159 1.57079 1.57079</pose>
          <geometry>
            <mesh>
              <scale>1 1 1</scale>
              <uri>/home/katerina/catkin_ws/src/robotiq/robotiq_2f_c2_gripper_visualization/meshes/robotiq_c2/collision/robotiq_85_gripper_joint_0_R.dae</uri>
            </mesh>
          </geometry>
          <max_contacts>10</max_contacts>
          <surface>
            <contact>
              <ode/>
            </contact>
            <bounce/>
            <friction>
              <torsional>
                <ode/>
              </torsional>
              <ode/>
            </friction>
          </surface>
        </collision>
        <collision name='robotiq_85_right_knuckle_link_fixed_joint_lump__robotiq_85_right_finger_link_collision_1'>
          <pose frame=''>0 0.041904 -0.030603 3.14159 1.57079 1.5706</pose>
          <geometry>
            <mesh>
              <scale>1 1 1</scale>
              <uri>/home/katerina/catkin_ws/src/robotiq/robotiq_2f_c2_gripper_visualization/meshes/robotiq_c2/collision/robotiq_85_gripper_joint_1_R.dae</uri>
            </mesh>
          </geometry>
          <max_contacts>10</max_contacts>
          <surface>
            <contact>
              <ode/>
            </contact>
            <bounce/>
            <friction>
              <torsional>
                <ode/>
              </torsional>
              <ode/>
            </friction>
          </surface>
        </collision>
        <visual name='robotiq_85_right_knuckle_link_visual'>
          <pose frame=''>0 0.04191 -0.0306 3.14159 1.57079 3e-06</pose>
          <geometry>
            <mesh>
              <scale>1 1 1</scale>
              <uri>/home/katerina/catkin_ws/src/robotiq/robotiq_2f_c2_gripper_visualization/meshes/robotiq_c2/visual/robotiq_85_gripper_joint_0_R.dae</uri>
            </mesh>
          </geometry>
        </visual>
        <visual name='robotiq_85_right_knuckle_link_fixed_joint_lump__robotiq_85_right_finger_link_visual_1'>
          <pose frame=''>0 0.041904 -0.030603 -3.14159 1.57079 -9.7e-05</pose>
          <geometry>
            <mesh>
              <scale>1 1 1</scale>
              <uri>/home/katerina/catkin_ws/src/robotiq/robotiq_2f_c2_gripper_visualization/meshes/robotiq_c2/visual/robotiq_85_gripper_joint_1_R.dae</uri>
            </mesh>
          </geometry>
        </visual>
        <self_collide>0</self_collide>
        <enable_wind>0</enable_wind>
        <kinematic>0</kinematic>
      </link>
      <joint name='robotiq_85_right_knuckle_joint' type='revolute'>
        <child>robotiq_85_right_knuckle_link</child>
        <parent>joint_a1_link</parent>
        <axis>
          <xyz>0.000796 0.999999 0.0007</xyz>
          <limit>
            <lower>0</lower>
            <upper>1.5707</upper>
            <effort>1000</effort>
            <velocity>2</velocity>
          </limit>
          <dynamics>
            <spring_reference>0</spring_reference>
            <spring_stiffness>0</spring_stiffness>
          </dynamics>
          <use_parent_model_frame>1</use_parent_model_frame>
        </axis>
      </joint>
      <link name='box_table'>
        <pose frame=''>0 -0.35 0.225 0 -0 0</pose>
        <inertial>
          <pose frame=''>0 0 0 0 -0 0</pose>
          <mass>1</mass>
          <inertia>
            <ixx>1</ixx>
            <ixy>0</ixy>
            <ixz>0</ixz>
            <iyy>1</iyy>
            <iyz>0</iyz>
            <izz>1</izz>
          </inertia>
        </inertial>
        <collision name='box_table_collision'>
          <pose frame=''>0 0 0 0 -0 0</pose>
          <geometry>
            <box>
              <size>1 0.7 0.5</size>
            </box>
          </geometry>
          <surface>
            <contact>
              <ode>
                <kp>1e+06</kp>
                <kd>1</kd>
              </ode>
            </contact>
            <friction>
              <ode>
                <mu>50</mu>
                <mu2>50</mu2>
              </ode>
              <torsional>
                <ode/>
              </torsional>
            </friction>
            <bounce/>
          </surface>
          <max_contacts>10</max_contacts>
        </collision>
        <visual name='box_table_visual'>
          <pose frame=''>0 0 0 0 -0 0</pose>
          <geometry>
            <box>
              <size>1 0.7 0.5</size>
            </box>
          </geometry>
          <material>
            <script>
              <name>Gazebo/Grey</name>
              <uri>file://media/materials/scripts/gazebo.material</uri>
            </script>
          </material>
        </visual>
        <gravity>1</gravity>
        <velocity_decay/>
        <self_collide>0</self_collide>
        <enable_wind>0</enable_wind>
        <kinematic>0</kinematic>
      </link>
      <joint name='table_box_joint' type='fixed'>
        <child>box_table</child>
        <parent>world</parent>
      </joint>
      <plugin name='gazebo_ros_control' filename='libgazebo_ros_control.so'>
        <robotNamespace>/robotiq_c2_model</robotNamespace>
      </plugin>
      <static>0</static>
      <plugin name='mimic_robotiq_85_4' filename='libroboticsgroup_upatras_gazebo_mimic_joint_plugin.so'>
        <joint>robotiq_85_left_knuckle_joint</joint>
        <mimicJoint>robotiq_85_right_knuckle_joint</mimicJoint>
        <multiplier>1.0</multiplier>
        <robotNamespace>/</robotNamespace>
      </plugin>
      <plugin name='mimic_robotiq_85_2' filename='libroboticsgroup_upatras_gazebo_mimic_joint_plugin.so'>
        <joint>robotiq_85_left_knuckle_joint</joint>
        <mimicJoint>robotiq_85_left_inner_knuckle_joint</mimicJoint>
        <offset>0.0</offset>
        <robotNamespace>/</robotNamespace>
      </plugin>
      <plugin name='mimic_robotiq_85_6' filename='libroboticsgroup_upatras_gazebo_mimic_joint_plugin.so'>
        <joint>robotiq_85_left_knuckle_joint</joint>
        <mimicJoint>robotiq_85_right_inner_knuckle_joint</mimicJoint>
        <offset>0.0</offset>
        <robotNamespace>/</robotNamespace>
      </plugin>
      <plugin name='mimic_robotiq_85_3' filename='libroboticsgroup_upatras_gazebo_mimic_joint_plugin.so'>
        <joint>robotiq_85_left_knuckle_joint</joint>
        <mimicJoint>robotiq_85_left_finger_tip_joint</mimicJoint>
        <multiplier>-1.0</multiplier>
        <robotNamespace>/</robotNamespace>
      </plugin>
      <plugin name='mimic_robotiq_85_5' filename='libroboticsgroup_upatras_gazebo_mimic_joint_plugin.so'>
        <joint>robotiq_85_left_knuckle_joint</joint>
        <mimicJoint>robotiq_85_right_finger_tip_joint</mimicJoint>
        <multiplier>-1.0</multiplier>
        <robotNamespace>/</robotNamespace>
      </plugin>
      <pose frame=''>0 0 0 0 -0 0</pose>
    </model>
    <model name='unit_box'>
      <link name='link'>
        <inertial>
          <mass>1</mass>
          <inertia>
            <ixx>0.166667</ixx>
            <ixy>0</ixy>
            <ixz>0</ixz>
            <iyy>0.166667</iyy>
            <iyz>0</iyz>
            <izz>0.166667</izz>
          </inertia>
          <pose frame=''>0 0 0 0 -0 0</pose>
        </inertial>
        <self_collide>0</self_collide>
        <enable_wind>0</enable_wind>
        <kinematic>0</kinematic>
        <pose frame=''>0 0 0 0 -0 0</pose>
        <gravity>1</gravity>
        <visual name='visual'>
          <geometry>
            <box>
              <size>0.05 0.05 0.05</size>
            </box>
          </geometry>
          <material>
            <script>
              <name>Gazebo/Red</name>
              <uri>file://media/materials/scripts/gazebo.material</uri>
            </script>
            <shader type='vertex'>
              <normal_map>__default__</normal_map>
            </shader>
            <ambient>0.3 0.3 0.3 1</ambient>
            <diffuse>0.7 0.7 0.7 1</diffuse>
            <specular>0.01 0.01 0.01 1</specular>
            <emissive>0 0 0 1</emissive>
          </material>
          <pose frame=''>0 0 0 0 -0 0</pose>
          <transparency>0</transparency>
          <cast_shadows>1</cast_shadows>
        </visual>
        <collision name='table_goal_collision'>
          <laser_retro>0</laser_retro>
          <max_contacts>10</max_contacts>
          <pose frame=''>0 0 0 0 -0 0</pose>
          <geometry>
            <box>
              <size>0.046401 0.051445 0.051847</size>
            </box>
          </geometry>
          <surface>
            <friction>
              <ode>
                <mu>1</mu>
                <mu2>1</mu2>
                <fdir1>0 0 0</fdir1>
                <slip1>0</slip1>
                <slip2>0</slip2>
              </ode>
              <torsional>
                <coefficient>1</coefficient>
                <patch_radius>0</patch_radius>
                <surface_radius>0</surface_radius>
                <use_patch_radius>1</use_patch_radius>
                <ode>
                  <slip>0</slip>
                </ode>
              </torsional>
            </friction>
            <bounce>
              <restitution_coefficient>0</restitution_coefficient>
              <threshold>1e+06</threshold>
            </bounce>
            <contact>
              <collide_without_contact>0</collide_without_contact>
              <collide_without_contact_bitmask>1</collide_without_contact_bitmask>
              <collide_bitmask>1</collide_bitmask>
              <ode>
                <soft_cfm>0</soft_cfm>
                <soft_erp>0.2</soft_erp>
                <kp>1e+13</kp>
                <kd>1</kd>
                <max_vel>0.01</max_vel>
                <min_depth>0</min_depth>
              </ode>
              <bullet>
                <split_impulse>1</split_impulse>
                <split_impulse_penetration_threshold>-0.01</split_impulse_penetration_threshold>
                <soft_cfm>0</soft_cfm>
                <soft_erp>0.2</soft_erp>
                <kp>1e+13</kp>
                <kd>1</kd>
              </bullet>
            </contact>
          </surface>
        </collision>
        <sensor name='my_contact' type='contact'>
        <plugin name="my_plugin" filename="libcontact.so"/>
          <contact>
            <collision>table_goal_collision</collision>
          </contact>
          <update_rate>5</update_rate>
        </sensor>
      </link>
      <static>0</static>
      <allow_auto_disable>1</allow_auto_disable>
      <pose frame=''>0.903631 -0.191081 0 0 -0 0</pose>
    </model>
    <state world_name='default'>
      <sim_time>1002 907000000</sim_time>
      <real_time>1004 223334203</real_time>
      <wall_time>1667837707 346366990</wall_time>
      <iterations>1002907</iterations>
      <model name='ground_plane'>
        <pose frame=''>0 0 0 0 -0 0</pose>
        <scale>1 1 1</scale>
        <link name='link'>
          <pose frame=''>0 0 0 0 -0 0</pose>
          <velocity>0 0 0 0 -0 0</velocity>
          <acceleration>0 0 0 0 -0 0</acceleration>
          <wrench>0 0 0 0 -0 0</wrench>
        </link>
      </model>
      <model name='robotiq_c2_model'>
        <pose frame=''>-0 -0 0 0 -0 0</pose>
        <scale>1 1 1</scale>
        <link name='arm_base_link'>
          <pose frame=''>2e-06 -0 0.625 0 -0 0</pose>
          <velocity>-1e-06 -0 -0 0 -1.1e-05 0</velocity>
          <acceleration>-0.001828 -0.000392 -0.000649 0.000638 -0.022512 0.000159</acceleration>
          <wrench>-0.001828 -0.000392 -0.000649 0 -0 0</wrench>
        </link>
        <link name='box'>
          <pose frame=''>-0 0 0.3 0 -0 0</pose>
          <velocity>0 0 0 0 9e-06 0</velocity>
          <acceleration>0 4e-06 0.000499 -0.000485 0.017449 -0.000121</acceleration>
          <wrench>0 4e-06 0.000499 0 -0 0</wrench>
        </link>
        <link name='box_table'>
          <pose frame=''>-0 -0.35 0.225 0 -0 0</pose>
          <velocity>-0 1e-06 -2e-06 -2e-06 -1e-06 0</velocity>
          <acceleration>0 0 -0 0 -0 0</acceleration>
          <wrench>0 0 -0 0 -0 0</wrench>
        </link>
        <link name='joint_a1_link'>
          <pose frame=''>-0.000197 -0.250001 0.674999 -0 -1e-06 1.57</pose>
          <velocity>-3e-06 -0 -1e-06 1e-06 -3.8e-05 -0</velocity>
          <acceleration>-0.004391 -0.000102 -0.003236 0.001898 -0.076086 0.000565</acceleration>
          <wrench>-0.013172 -0.000307 -0.009708 0 -0 0</wrench>
        </link>
        <link name='robotiq_85_left_finger_tip_link'>
          <pose frame=''>-0.051814 -0.553977 0.55099 -1.56782 0.000894 -1.57159</pose>
          <velocity>3e-06 0 -5e-06 1e-06 -6.4e-05 0</velocity>
          <acceleration>0.005647 9.9e-05 -0.009036 0.002296 -0.102874 0.000623</acceleration>
          <wrench>0.005647 9.9e-05 -0.009036 0 -0 0</wrench>
        </link>
        <link name='robotiq_85_left_inner_knuckle_link'>
          <pose frame=''>-0.013139 -0.554045 0.593065 -1.56782 0.000894 -1.57159</pose>
          <velocity>1e-06 0 -3e-06 1e-06 -6.3e-05 -0</velocity>
          <acceleration>0.001987 3e-05 -0.005773 0.002342 -0.102359 0.000639</acceleration>
          <wrench>0.001987 3e-05 -0.005773 0 -0 0</wrench>
        </link>
        <link name='robotiq_85_left_knuckle_link'>
          <pose frame=''>-0.031039 -0.554036 0.599586 1.57396 0.000894 -1.57159</pose>
          <velocity>0 -0 -3e-06 1e-06 1e-06 0</velocity>
          <acceleration>0.000781 -2e-05 -0.006506 0.002249 0.002066 0.000669</acceleration>
          <wrench>0.001562 -3.9e-05 -0.013011 0 -0 0</wrench>
        </link>
        <link name='robotiq_85_right_finger_tip_link'>
          <pose frame=''>0.050928 -0.554066 0.550983 -1.56763 -0.000701 1.57</pose>
          <velocity>3e-06 0 1e-06 1e-06 -4.8e-05 0</velocity>
          <acceleration>0.004748 0.000142 0.001112 0.002112 -0.088718 0.000577</acceleration>
          <wrench>0.004748 0.000142 0.001112 0 -0 0</wrench>
        </link>
        <link name='robotiq_85_right_inner_knuckle_link'>
          <pose frame=''>0.012261 -0.554066 0.593066 -1.56763 -0.000701 1.57</pose>
          <velocity>1e-06 0 -1e-06 1e-06 -5.6e-05 0</velocity>
          <acceleration>0.001276 3.6e-05 -0.002159 0.002148 -0.09632 0.000585</acceleration>
          <wrench>0.001276 3.6e-05 -0.002159 0 -0 0</wrench>
        </link>
        <link name='robotiq_85_right_knuckle_link'>
          <pose frame=''>0.030161 -0.554085 0.599586 1.57377 -0.000701 1.57</pose>
          <velocity>-0 0 -0 1e-06 -4.6e-05 0</velocity>
          <acceleration>-0.000298 2.7e-05 0.000428 0.002034 -0.085132 0.000546</acceleration>
          <wrench>-0.000595 5.3e-05 0.000856 0 -0 0</wrench>
        </link>
      </model>
      <model name='unit_box'>
        <pose frame=''>-0.144819 -0.488213 0.500921 0 -0 0.006822</pose>
        <scale>1 1 1</scale>
        <link name='link'>
          <pose frame=''>-0.144819 -0.488213 0.500921 0 -0 0.006822</pose>
          <velocity>-1e-06 1e-06 2.1e-05 -0 -2e-06 5e-06</velocity>
          <acceleration>-0.000628 0.001308 0.020673 -0.000137 -0.002144 0.004634</acceleration>
          <wrench>-0.000628 0.001308 0.020673 0 -0 0</wrench>
        </link>
      </model>
      <light name='sun'>
        <pose frame=''>0 0 10 0 -0 0</pose>
      </light>
    </state>
    <gui fullscreen='0'>
      <camera name='user_camera'>
        <pose frame=''>0.051867 -1.42317 1.34033 0 0.844 1.512</pose>
        <view_controller>orbit</view_controller>
        <projection_type>perspective</projection_type>
      </camera>
    </gui>
  </world>
</sdf>
